*** Starting uWSGI 2.0.20 (64bit) on [Tue Nov  2 12:39:06 2021] ***
compiled with version: 6.3.0 20170516 on 02 November 2021 12:38:16
os: Linux-4.14.248-189.473.amzn2.x86_64 #1 SMP Mon Sep 27 05:52:26 UTC 2021
nodename: 4dacf0ea01ed
machine: x86_64
clock source: unix
pcre jit disabled
detected number of CPU cores: 1
current working directory: /srv/docker-server
detected binary path: /usr/local/bin/uwsgi
uWSGI running as root, you can use --uid/--gid/--chroot options
*** WARNING: you are running uWSGI as root !!! (use the --uid flag) *** 
chdir() to /srv/docker-server
your memory page size is 4096 bytes
detected max file descriptor number: 32768
lock engine: pthread robust mutexes
thunder lock: disabled (you can enable it with --thunder-lock)
uwsgi socket 0 bound to UNIX address /srv/docker-server/apps.sock fd 3
uWSGI running as root, you can use --uid/--gid/--chroot options
*** WARNING: you are running uWSGI as root !!! (use the --uid flag) *** 
Python version: 3.6.7 (default, Nov 16 2018, 22:33:19)  [GCC 6.3.0 20170516]
Python main interpreter initialized at 0x562b03b4b4d0
uWSGI running as root, you can use --uid/--gid/--chroot options
*** WARNING: you are running uWSGI as root !!! (use the --uid flag) *** 
python threads support enabled
your server socket listen backlog is limited to 100 connections
your mercy for graceful operations on workers is 60 seconds
mapped 166752 bytes (162 KB) for 2 cores
*** Operational MODE: threaded ***
WSGI app 0 (mountpoint='') ready in 1 seconds on interpreter 0x562b03b4b4d0 pid: 1 (default app)
uWSGI running as root, you can use --uid/--gid/--chroot options
*** WARNING: you are running uWSGI as root !!! (use the --uid flag) *** 
*** uWSGI is running in multiple interpreter mode ***
spawned uWSGI master process (pid: 1)
spawned uWSGI worker 1 (pid: 8, cores: 2)
[pid: 8|app: 0|req: 1/1] 203.255.57.152 () {42 vars in 755 bytes} [Tue Nov  2 21:39:40 2021] GET / => generated 1908 bytes in 60 msecs (HTTP/1.1 200) 6 headers in 319 bytes (2 switches on core 0)
Not Found: /favicon.ico
[pid: 8|app: 0|req: 2/2] 203.255.57.152 () {44 vars in 796 bytes} [Tue Nov  2 21:39:42 2021] GET /favicon.ico => generated 2410 bytes in 5 msecs (HTTP/1.1 404) 4 headers in 129 bytes (1 switches on core 1)
...brutally killing workers...
worker 1 buried after 1 seconds
binary reloading uWSGI...
chdir() to /srv/docker-server
closing all non-uwsgi socket fds > 2 (max_fd = 32768)...
found fd 3 mapped to socket 0 (/srv/docker-server/apps.sock)
running /usr/local/bin/uwsgi
[uWSGI] getting INI configuration from uwsgi.ini
*** Starting uWSGI 2.0.20 (64bit) on [Tue Nov  2 21:42:34 2021] ***
compiled with version: 6.3.0 20170516 on 02 November 2021 12:38:16
os: Linux-4.14.248-189.473.amzn2.x86_64 #1 SMP Mon Sep 27 05:52:26 UTC 2021
nodename: 4dacf0ea01ed
machine: x86_64
clock source: unix
pcre jit disabled
detected number of CPU cores: 1
current working directory: /srv/docker-server
detected binary path: /usr/local/bin/uwsgi
uWSGI running as root, you can use --uid/--gid/--chroot options
*** WARNING: you are running uWSGI as root !!! (use the --uid flag) *** 
chdir() to /srv/docker-server
your memory page size is 4096 bytes
detected max file descriptor number: 32768
lock engine: pthread robust mutexes
thunder lock: disabled (you can enable it with --thunder-lock)
uwsgi socket 0 inherited UNIX address /srv/docker-server/apps.sock fd 3
uWSGI running as root, you can use --uid/--gid/--chroot options
*** WARNING: you are running uWSGI as root !!! (use the --uid flag) *** 
Python version: 3.6.7 (default, Nov 16 2018, 22:33:19)  [GCC 6.3.0 20170516]
Python main interpreter initialized at 0x55617c2ba4b0
uWSGI running as root, you can use --uid/--gid/--chroot options
*** WARNING: you are running uWSGI as root !!! (use the --uid flag) *** 
python threads support enabled
your server socket listen backlog is limited to 100 connections
your mercy for graceful operations on workers is 60 seconds
mapped 166752 bytes (162 KB) for 2 cores
*** Operational MODE: threaded ***
WSGI app 0 (mountpoint='') ready in 0 seconds on interpreter 0x55617c2ba4b0 pid: 1 (default app)
uWSGI running as root, you can use --uid/--gid/--chroot options
*** WARNING: you are running uWSGI as root !!! (use the --uid flag) *** 
*** uWSGI is running in multiple interpreter mode ***
gracefully (RE)spawned uWSGI master process (pid: 1)
spawned uWSGI worker 1 (pid: 11, cores: 2)
Tue Nov  2 21:42:43 2021 - uWSGI worker 1 screams: UAAAAAAH my master disconnected: i will kill myself !!!
*** Starting uWSGI 2.0.20 (64bit) on [Tue Nov  2 12:43:02 2021] ***
compiled with version: 6.3.0 20170516 on 02 November 2021 12:38:16
os: Linux-4.14.248-189.473.amzn2.x86_64 #1 SMP Mon Sep 27 05:52:26 UTC 2021
nodename: 38fcb847a835
machine: x86_64
clock source: unix
pcre jit disabled
detected number of CPU cores: 1
current working directory: /srv/docker-server
detected binary path: /usr/local/bin/uwsgi
uWSGI running as root, you can use --uid/--gid/--chroot options
*** WARNING: you are running uWSGI as root !!! (use the --uid flag) *** 
chdir() to /srv/docker-server
your memory page size is 4096 bytes
detected max file descriptor number: 32768
lock engine: pthread robust mutexes
thunder lock: disabled (you can enable it with --thunder-lock)
uwsgi socket 0 bound to UNIX address /srv/docker-server/apps.sock fd 3
uWSGI running as root, you can use --uid/--gid/--chroot options
*** WARNING: you are running uWSGI as root !!! (use the --uid flag) *** 
Python version: 3.6.7 (default, Nov 16 2018, 22:33:19)  [GCC 6.3.0 20170516]
Python main interpreter initialized at 0x5570f9db34d0
uWSGI running as root, you can use --uid/--gid/--chroot options
*** WARNING: you are running uWSGI as root !!! (use the --uid flag) *** 
python threads support enabled
your server socket listen backlog is limited to 100 connections
your mercy for graceful operations on workers is 60 seconds
mapped 166752 bytes (162 KB) for 2 cores
*** Operational MODE: threaded ***
WSGI app 0 (mountpoint='') ready in 1 seconds on interpreter 0x5570f9db34d0 pid: 1 (default app)
uWSGI running as root, you can use --uid/--gid/--chroot options
*** WARNING: you are running uWSGI as root !!! (use the --uid flag) *** 
*** uWSGI is running in multiple interpreter mode ***
spawned uWSGI master process (pid: 1)
spawned uWSGI worker 1 (pid: 8, cores: 2)
...brutally killing workers...
worker 1 buried after 1 seconds
binary reloading uWSGI...
chdir() to /srv/docker-server
closing all non-uwsgi socket fds > 2 (max_fd = 32768)...
found fd 3 mapped to socket 0 (/srv/docker-server/apps.sock)
running /usr/local/bin/uwsgi
[uWSGI] getting INI configuration from uwsgi.ini
*** Starting uWSGI 2.0.20 (64bit) on [Tue Nov  2 21:43:39 2021] ***
compiled with version: 6.3.0 20170516 on 02 November 2021 12:38:16
os: Linux-4.14.248-189.473.amzn2.x86_64 #1 SMP Mon Sep 27 05:52:26 UTC 2021
nodename: 38fcb847a835
machine: x86_64
clock source: unix
pcre jit disabled
detected number of CPU cores: 1
current working directory: /srv/docker-server
detected binary path: /usr/local/bin/uwsgi
uWSGI running as root, you can use --uid/--gid/--chroot options
*** WARNING: you are running uWSGI as root !!! (use the --uid flag) *** 
chdir() to /srv/docker-server
your memory page size is 4096 bytes
detected max file descriptor number: 32768
lock engine: pthread robust mutexes
thunder lock: disabled (you can enable it with --thunder-lock)
uwsgi socket 0 inherited UNIX address /srv/docker-server/apps.sock fd 3
uWSGI running as root, you can use --uid/--gid/--chroot options
*** WARNING: you are running uWSGI as root !!! (use the --uid flag) *** 
Python version: 3.6.7 (default, Nov 16 2018, 22:33:19)  [GCC 6.3.0 20170516]
Python main interpreter initialized at 0x5575e12474b0
uWSGI running as root, you can use --uid/--gid/--chroot options
*** WARNING: you are running uWSGI as root !!! (use the --uid flag) *** 
python threads support enabled
your server socket listen backlog is limited to 100 connections
your mercy for graceful operations on workers is 60 seconds
mapped 166752 bytes (162 KB) for 2 cores
*** Operational MODE: threaded ***
WSGI app 0 (mountpoint='') ready in 1 seconds on interpreter 0x5575e12474b0 pid: 1 (default app)
uWSGI running as root, you can use --uid/--gid/--chroot options
*** WARNING: you are running uWSGI as root !!! (use the --uid flag) *** 
*** uWSGI is running in multiple interpreter mode ***
gracefully (RE)spawned uWSGI master process (pid: 1)
spawned uWSGI worker 1 (pid: 11, cores: 2)
Tue Nov  2 21:43:48 2021 - uWSGI worker 1 screams: UAAAAAAH my master disconnected: i will kill myself !!!
*** Starting uWSGI 2.0.20 (64bit) on [Tue Nov  2 12:43:49 2021] ***
compiled with version: 6.3.0 20170516 on 02 November 2021 12:38:16
os: Linux-4.14.248-189.473.amzn2.x86_64 #1 SMP Mon Sep 27 05:52:26 UTC 2021
nodename: 38fcb847a835
machine: x86_64
clock source: unix
pcre jit disabled
detected number of CPU cores: 1
current working directory: /srv/docker-server
detected binary path: /usr/local/bin/uwsgi
uWSGI running as root, you can use --uid/--gid/--chroot options
*** WARNING: you are running uWSGI as root !!! (use the --uid flag) *** 
chdir() to /srv/docker-server
your memory page size is 4096 bytes
detected max file descriptor number: 32768
lock engine: pthread robust mutexes
thunder lock: disabled (you can enable it with --thunder-lock)
uwsgi socket 0 bound to UNIX address /srv/docker-server/apps.sock fd 3
uWSGI running as root, you can use --uid/--gid/--chroot options
*** WARNING: you are running uWSGI as root !!! (use the --uid flag) *** 
Python version: 3.6.7 (default, Nov 16 2018, 22:33:19)  [GCC 6.3.0 20170516]
Python main interpreter initialized at 0x55b47a0cf4d0
uWSGI running as root, you can use --uid/--gid/--chroot options
*** WARNING: you are running uWSGI as root !!! (use the --uid flag) *** 
python threads support enabled
your server socket listen backlog is limited to 100 connections
your mercy for graceful operations on workers is 60 seconds
mapped 166752 bytes (162 KB) for 2 cores
*** Operational MODE: threaded ***
WSGI app 0 (mountpoint='') ready in 0 seconds on interpreter 0x55b47a0cf4d0 pid: 1 (default app)
uWSGI running as root, you can use --uid/--gid/--chroot options
*** WARNING: you are running uWSGI as root !!! (use the --uid flag) *** 
*** uWSGI is running in multiple interpreter mode ***
spawned uWSGI master process (pid: 1)
spawned uWSGI worker 1 (pid: 8, cores: 2)
[pid: 8|app: 0|req: 1/1] 203.255.63.30 () {42 vars in 760 bytes} [Tue Nov  2 21:57:17 2021] GET / => generated 1908 bytes in 43 msecs (HTTP/1.1 200) 6 headers in 319 bytes (1 switches on core 0)
Not Found: /favicon.ico
[pid: 8|app: 0|req: 2/2] 203.255.63.30 () {44 vars in 801 bytes} [Tue Nov  2 21:57:18 2021] GET /favicon.ico => generated 2410 bytes in 6 msecs (HTTP/1.1 404) 4 headers in 129 bytes (1 switches on core 1)
[pid: 8|app: 0|req: 3/3] 23.94.145.169 () {38 vars in 580 bytes} [Tue Nov  2 22:25:47 2021] GET / => generated 1908 bytes in 5 msecs (HTTP/1.1 200) 6 headers in 319 bytes (1 switches on core 0)
[pid: 8|app: 0|req: 4/4] 203.255.57.152 () {44 vars in 843 bytes} [Tue Nov  2 22:32:43 2021] GET / => generated 1911 bytes in 5 msecs (HTTP/1.1 200) 6 headers in 319 bytes (1 switches on core 1)
[pid: 8|app: 0|req: 5/5] 203.255.57.152 () {46 vars in 875 bytes} [Tue Nov  2 22:35:26 2021] GET / => generated 1911 bytes in 4 msecs (HTTP/1.1 200) 6 headers in 319 bytes (1 switches on core 0)
[pid: 8|app: 0|req: 6/6] 203.255.57.152 () {42 vars in 762 bytes} [Tue Nov  2 22:35:47 2021] GET / => generated 1911 bytes in 5 msecs (HTTP/1.1 200) 6 headers in 319 bytes (1 switches on core 1)
Not Found: /favicon.ico
[pid: 8|app: 0|req: 7/7] 203.255.57.152 () {44 vars in 804 bytes} [Tue Nov  2 22:35:48 2021] GET /favicon.ico => generated 2411 bytes in 5 msecs (HTTP/1.1 404) 4 headers in 129 bytes (1 switches on core 0)
Internal Server Error: /
Traceback (most recent call last):
  File "/usr/local/lib/python3.6/site-packages/django/contrib/sessions/backends/base.py", line 199, in _get_session
    return self._session_cache
AttributeError: 'SessionStore' object has no attribute '_session_cache'

During handling of the above exception, another exception occurred:

Traceback (most recent call last):
  File "/usr/local/lib/python3.6/site-packages/django/db/backends/utils.py", line 86, in _execute
    return self.cursor.execute(sql, params)
  File "/usr/local/lib/python3.6/site-packages/django/db/backends/sqlite3/base.py", line 396, in execute
    return Database.Cursor.execute(self, query, params)
sqlite3.OperationalError: no such table: django_session

The above exception was the direct cause of the following exception:

Traceback (most recent call last):
  File "/usr/local/lib/python3.6/site-packages/django/core/handlers/exception.py", line 34, in inner
    response = get_response(request)
  File "/usr/local/lib/python3.6/site-packages/django/core/handlers/base.py", line 115, in _get_response
    response = self.process_exception_by_middleware(e, request)
  File "/usr/local/lib/python3.6/site-packages/django/core/handlers/base.py", line 113, in _get_response
    response = wrapped_callback(request, *callback_args, **callback_kwargs)
  File "./jariyo/views/base_views.py", line 11, in index
    if cur_user.is_authenticated:
  File "/usr/local/lib/python3.6/site-packages/django/utils/functional.py", line 224, in inner
    self._setup()
  File "/usr/local/lib/python3.6/site-packages/django/utils/functional.py", line 360, in _setup
    self._wrapped = self._setupfunc()
  File "/usr/local/lib/python3.6/site-packages/django/contrib/auth/middleware.py", line 24, in <lambda>
    request.user = SimpleLazyObject(lambda: get_user(request))
  File "/usr/local/lib/python3.6/site-packages/django/contrib/auth/middleware.py", line 12, in get_user
    request._cached_user = auth.get_user(request)
  File "/usr/local/lib/python3.6/site-packages/django/contrib/auth/__init__.py", line 173, in get_user
    user_id = _get_user_session_key(request)
  File "/usr/local/lib/python3.6/site-packages/django/contrib/auth/__init__.py", line 58, in _get_user_session_key
    return get_user_model()._meta.pk.to_python(request.session[SESSION_KEY])
  File "/usr/local/lib/python3.6/site-packages/django/contrib/sessions/backends/base.py", line 64, in __getitem__
    return self._session[key]
  File "/usr/local/lib/python3.6/site-packages/django/contrib/sessions/backends/base.py", line 204, in _get_session
    self._session_cache = self.load()
  File "/usr/local/lib/python3.6/site-packages/django/contrib/sessions/backends/db.py", line 43, in load
    s = self._get_session_from_db()
  File "/usr/local/lib/python3.6/site-packages/django/contrib/sessions/backends/db.py", line 34, in _get_session_from_db
    expire_date__gt=timezone.now()
  File "/usr/local/lib/python3.6/site-packages/django/db/models/manager.py", line 82, in manager_method
    return getattr(self.get_queryset(), name)(*args, **kwargs)
  File "/usr/local/lib/python3.6/site-packages/django/db/models/query.py", line 411, in get
    num = len(clone)
  File "/usr/local/lib/python3.6/site-packages/django/db/models/query.py", line 258, in __len__
    self._fetch_all()
  File "/usr/local/lib/python3.6/site-packages/django/db/models/query.py", line 1261, in _fetch_all
    self._result_cache = list(self._iterable_class(self))
  File "/usr/local/lib/python3.6/site-packages/django/db/models/query.py", line 57, in __iter__
    results = compiler.execute_sql(chunked_fetch=self.chunked_fetch, chunk_size=self.chunk_size)
  File "/usr/local/lib/python3.6/site-packages/django/db/models/sql/compiler.py", line 1151, in execute_sql
    cursor.execute(sql, params)
  File "/usr/local/lib/python3.6/site-packages/django/db/backends/utils.py", line 100, in execute
    return super().execute(sql, params)
  File "/usr/local/lib/python3.6/site-packages/django/db/backends/utils.py", line 68, in execute
    return self._execute_with_wrappers(sql, params, many=False, executor=self._execute)
  File "/usr/local/lib/python3.6/site-packages/django/db/backends/utils.py", line 77, in _execute_with_wrappers
    return executor(sql, params, many, context)
  File "/usr/local/lib/python3.6/site-packages/django/db/backends/utils.py", line 86, in _execute
    return self.cursor.execute(sql, params)
  File "/usr/local/lib/python3.6/site-packages/django/db/utils.py", line 90, in __exit__
    raise dj_exc_value.with_traceback(traceback) from exc_value
  File "/usr/local/lib/python3.6/site-packages/django/db/backends/utils.py", line 86, in _execute
    return self.cursor.execute(sql, params)
  File "/usr/local/lib/python3.6/site-packages/django/db/backends/sqlite3/base.py", line 396, in execute
    return Database.Cursor.execute(self, query, params)
django.db.utils.OperationalError: no such table: django_session
[pid: 8|app: 0|req: 8/8] 203.255.57.152 () {44 vars in 913 bytes} [Tue Nov  2 22:35:56 2021] GET / => generated 173488 bytes in 125 msecs (HTTP/1.1 500) 5 headers in 157 bytes (1 switches on core 1)
[pid: 8|app: 0|req: 9/9] 203.255.57.152 () {46 vars in 875 bytes} [Tue Nov  2 22:36:01 2021] GET / => generated 1911 bytes in 4 msecs (HTTP/1.1 200) 6 headers in 319 bytes (1 switches on core 0)
[pid: 8|app: 0|req: 10/10] 203.255.57.152 () {46 vars in 875 bytes} [Tue Nov  2 22:36:02 2021] GET / => generated 1911 bytes in 4 msecs (HTTP/1.1 200) 6 headers in 319 bytes (1 switches on core 1)
Internal Server Error: /
Traceback (most recent call last):
  File "/usr/local/lib/python3.6/site-packages/django/contrib/sessions/backends/base.py", line 199, in _get_session
    return self._session_cache
AttributeError: 'SessionStore' object has no attribute '_session_cache'

During handling of the above exception, another exception occurred:

Traceback (most recent call last):
  File "/usr/local/lib/python3.6/site-packages/django/db/backends/utils.py", line 86, in _execute
    return self.cursor.execute(sql, params)
  File "/usr/local/lib/python3.6/site-packages/django/db/backends/sqlite3/base.py", line 396, in execute
    return Database.Cursor.execute(self, query, params)
sqlite3.OperationalError: no such table: django_session

The above exception was the direct cause of the following exception:

Traceback (most recent call last):
  File "/usr/local/lib/python3.6/site-packages/django/core/handlers/exception.py", line 34, in inner
    response = get_response(request)
  File "/usr/local/lib/python3.6/site-packages/django/core/handlers/base.py", line 115, in _get_response
    response = self.process_exception_by_middleware(e, request)
  File "/usr/local/lib/python3.6/site-packages/django/core/handlers/base.py", line 113, in _get_response
    response = wrapped_callback(request, *callback_args, **callback_kwargs)
  File "./jariyo/views/base_views.py", line 11, in index
    if cur_user.is_authenticated:
  File "/usr/local/lib/python3.6/site-packages/django/utils/functional.py", line 224, in inner
    self._setup()
  File "/usr/local/lib/python3.6/site-packages/django/utils/functional.py", line 360, in _setup
    self._wrapped = self._setupfunc()
  File "/usr/local/lib/python3.6/site-packages/django/contrib/auth/middleware.py", line 24, in <lambda>
    request.user = SimpleLazyObject(lambda: get_user(request))
  File "/usr/local/lib/python3.6/site-packages/django/contrib/auth/middleware.py", line 12, in get_user
    request._cached_user = auth.get_user(request)
  File "/usr/local/lib/python3.6/site-packages/django/contrib/auth/__init__.py", line 173, in get_user
    user_id = _get_user_session_key(request)
  File "/usr/local/lib/python3.6/site-packages/django/contrib/auth/__init__.py", line 58, in _get_user_session_key
    return get_user_model()._meta.pk.to_python(request.session[SESSION_KEY])
  File "/usr/local/lib/python3.6/site-packages/django/contrib/sessions/backends/base.py", line 64, in __getitem__
    return self._session[key]
  File "/usr/local/lib/python3.6/site-packages/django/contrib/sessions/backends/base.py", line 204, in _get_session
    self._session_cache = self.load()
  File "/usr/local/lib/python3.6/site-packages/django/contrib/sessions/backends/db.py", line 43, in load
    s = self._get_session_from_db()
  File "/usr/local/lib/python3.6/site-packages/django/contrib/sessions/backends/db.py", line 34, in _get_session_from_db
    expire_date__gt=timezone.now()
  File "/usr/local/lib/python3.6/site-packages/django/db/models/manager.py", line 82, in manager_method
    return getattr(self.get_queryset(), name)(*args, **kwargs)
  File "/usr/local/lib/python3.6/site-packages/django/db/models/query.py", line 411, in get
    num = len(clone)
  File "/usr/local/lib/python3.6/site-packages/django/db/models/query.py", line 258, in __len__
    self._fetch_all()
  File "/usr/local/lib/python3.6/site-packages/django/db/models/query.py", line 1261, in _fetch_all
    self._result_cache = list(self._iterable_class(self))
  File "/usr/local/lib/python3.6/site-packages/django/db/models/query.py", line 57, in __iter__
    results = compiler.execute_sql(chunked_fetch=self.chunked_fetch, chunk_size=self.chunk_size)
  File "/usr/local/lib/python3.6/site-packages/django/db/models/sql/compiler.py", line 1151, in execute_sql
    cursor.execute(sql, params)
  File "/usr/local/lib/python3.6/site-packages/django/db/backends/utils.py", line 100, in execute
    return super().execute(sql, params)
  File "/usr/local/lib/python3.6/site-packages/django/db/backends/utils.py", line 68, in execute
    return self._execute_with_wrappers(sql, params, many=False, executor=self._execute)
  File "/usr/local/lib/python3.6/site-packages/django/db/backends/utils.py", line 77, in _execute_with_wrappers
    return executor(sql, params, many, context)
  File "/usr/local/lib/python3.6/site-packages/django/db/backends/utils.py", line 86, in _execute
    return self.cursor.execute(sql, params)
  File "/usr/local/lib/python3.6/site-packages/django/db/utils.py", line 90, in __exit__
    raise dj_exc_value.with_traceback(traceback) from exc_value
  File "/usr/local/lib/python3.6/site-packages/django/db/backends/utils.py", line 86, in _execute
    return self.cursor.execute(sql, params)
  File "/usr/local/lib/python3.6/site-packages/django/db/backends/sqlite3/base.py", line 396, in execute
    return Database.Cursor.execute(self, query, params)
django.db.utils.OperationalError: no such table: django_session
[pid: 8|app: 0|req: 11/11] 203.255.57.152 () {46 vars in 944 bytes} [Tue Nov  2 22:36:03 2021] GET / => generated 173627 bytes in 80 msecs (HTTP/1.1 500) 5 headers in 157 bytes (1 switches on core 0)
[pid: 8|app: 0|req: 12/12] 203.255.57.152 () {46 vars in 875 bytes} [Tue Nov  2 22:36:15 2021] GET / => generated 1911 bytes in 4 msecs (HTTP/1.1 200) 6 headers in 319 bytes (1 switches on core 1)
Internal Server Error: /
Traceback (most recent call last):
  File "/usr/local/lib/python3.6/site-packages/django/contrib/sessions/backends/base.py", line 199, in _get_session
    return self._session_cache
AttributeError: 'SessionStore' object has no attribute '_session_cache'

During handling of the above exception, another exception occurred:

Traceback (most recent call last):
  File "/usr/local/lib/python3.6/site-packages/django/db/backends/utils.py", line 86, in _execute
    return self.cursor.execute(sql, params)
  File "/usr/local/lib/python3.6/site-packages/django/db/backends/sqlite3/base.py", line 396, in execute
    return Database.Cursor.execute(self, query, params)
sqlite3.OperationalError: no such table: django_session

The above exception was the direct cause of the following exception:

Traceback (most recent call last):
  File "/usr/local/lib/python3.6/site-packages/django/core/handlers/exception.py", line 34, in inner
    response = get_response(request)
  File "/usr/local/lib/python3.6/site-packages/django/core/handlers/base.py", line 115, in _get_response
    response = self.process_exception_by_middleware(e, request)
  File "/usr/local/lib/python3.6/site-packages/django/core/handlers/base.py", line 113, in _get_response
    response = wrapped_callback(request, *callback_args, **callback_kwargs)
  File "./jariyo/views/base_views.py", line 11, in index
    if cur_user.is_authenticated:
  File "/usr/local/lib/python3.6/site-packages/django/utils/functional.py", line 224, in inner
    self._setup()
  File "/usr/local/lib/python3.6/site-packages/django/utils/functional.py", line 360, in _setup
    self._wrapped = self._setupfunc()
  File "/usr/local/lib/python3.6/site-packages/django/contrib/auth/middleware.py", line 24, in <lambda>
    request.user = SimpleLazyObject(lambda: get_user(request))
  File "/usr/local/lib/python3.6/site-packages/django/contrib/auth/middleware.py", line 12, in get_user
    request._cached_user = auth.get_user(request)
  File "/usr/local/lib/python3.6/site-packages/django/contrib/auth/__init__.py", line 173, in get_user
    user_id = _get_user_session_key(request)
  File "/usr/local/lib/python3.6/site-packages/django/contrib/auth/__init__.py", line 58, in _get_user_session_key
    return get_user_model()._meta.pk.to_python(request.session[SESSION_KEY])
  File "/usr/local/lib/python3.6/site-packages/django/contrib/sessions/backends/base.py", line 64, in __getitem__
    return self._session[key]
  File "/usr/local/lib/python3.6/site-packages/django/contrib/sessions/backends/base.py", line 204, in _get_session
    self._session_cache = self.load()
  File "/usr/local/lib/python3.6/site-packages/django/contrib/sessions/backends/db.py", line 43, in load
    s = self._get_session_from_db()
  File "/usr/local/lib/python3.6/site-packages/django/contrib/sessions/backends/db.py", line 34, in _get_session_from_db
    expire_date__gt=timezone.now()
  File "/usr/local/lib/python3.6/site-packages/django/db/models/manager.py", line 82, in manager_method
    return getattr(self.get_queryset(), name)(*args, **kwargs)
  File "/usr/local/lib/python3.6/site-packages/django/db/models/query.py", line 411, in get
    num = len(clone)
  File "/usr/local/lib/python3.6/site-packages/django/db/models/query.py", line 258, in __len__
    self._fetch_all()
  File "/usr/local/lib/python3.6/site-packages/django/db/models/query.py", line 1261, in _fetch_all
    self._result_cache = list(self._iterable_class(self))
  File "/usr/local/lib/python3.6/site-packages/django/db/models/query.py", line 57, in __iter__
    results = compiler.execute_sql(chunked_fetch=self.chunked_fetch, chunk_size=self.chunk_size)
  File "/usr/local/lib/python3.6/site-packages/django/db/models/sql/compiler.py", line 1151, in execute_sql
    cursor.execute(sql, params)
  File "/usr/local/lib/python3.6/site-packages/django/db/backends/utils.py", line 100, in execute
    return super().execute(sql, params)
  File "/usr/local/lib/python3.6/site-packages/django/db/backends/utils.py", line 68, in execute
    return self._execute_with_wrappers(sql, params, many=False, executor=self._execute)
  File "/usr/local/lib/python3.6/site-packages/django/db/backends/utils.py", line 77, in _execute_with_wrappers
    return executor(sql, params, many, context)
  File "/usr/local/lib/python3.6/site-packages/django/db/backends/utils.py", line 86, in _execute
    return self.cursor.execute(sql, params)
  File "/usr/local/lib/python3.6/site-packages/django/db/utils.py", line 90, in __exit__
    raise dj_exc_value.with_traceback(traceback) from exc_value
  File "/usr/local/lib/python3.6/site-packages/django/db/backends/utils.py", line 86, in _execute
    return self.cursor.execute(sql, params)
  File "/usr/local/lib/python3.6/site-packages/django/db/backends/sqlite3/base.py", line 396, in execute
    return Database.Cursor.execute(self, query, params)
django.db.utils.OperationalError: no such table: django_session
[pid: 8|app: 0|req: 13/13] 203.255.57.152 () {46 vars in 944 bytes} [Tue Nov  2 22:36:18 2021] GET / => generated 173629 bytes in 80 msecs (HTTP/1.1 500) 5 headers in 157 bytes (1 switches on core 0)
[pid: 8|app: 0|req: 14/14] 203.255.57.152 () {46 vars in 882 bytes} [Tue Nov  2 22:36:33 2021] GET / => generated 1911 bytes in 4 msecs (HTTP/1.1 200) 6 headers in 319 bytes (1 switches on core 1)
[pid: 8|app: 0|req: 15/15] 203.255.57.152 () {46 vars in 882 bytes} [Tue Nov  2 22:36:34 2021] GET / => generated 1911 bytes in 4 msecs (HTTP/1.1 200) 6 headers in 319 bytes (1 switches on core 0)
[pid: 8|app: 0|req: 16/16] 203.255.57.152 () {46 vars in 882 bytes} [Tue Nov  2 22:36:35 2021] GET / => generated 1911 bytes in 5 msecs (HTTP/1.1 200) 6 headers in 319 bytes (1 switches on core 1)
[pid: 8|app: 0|req: 17/17] 203.255.57.152 () {46 vars in 882 bytes} [Tue Nov  2 22:36:36 2021] GET / => generated 1911 bytes in 5 msecs (HTTP/1.1 200) 6 headers in 319 bytes (1 switches on core 0)
[pid: 8|app: 0|req: 18/18] 203.255.57.152 () {46 vars in 882 bytes} [Tue Nov  2 22:36:37 2021] GET / => generated 1911 bytes in 5 msecs (HTTP/1.1 200) 6 headers in 319 bytes (1 switches on core 1)
Internal Server Error: /
Traceback (most recent call last):
  File "/usr/local/lib/python3.6/site-packages/django/contrib/sessions/backends/base.py", line 199, in _get_session
    return self._session_cache
AttributeError: 'SessionStore' object has no attribute '_session_cache'

During handling of the above exception, another exception occurred:

Traceback (most recent call last):
  File "/usr/local/lib/python3.6/site-packages/django/db/backends/utils.py", line 86, in _execute
    return self.cursor.execute(sql, params)
  File "/usr/local/lib/python3.6/site-packages/django/db/backends/sqlite3/base.py", line 396, in execute
    return Database.Cursor.execute(self, query, params)
sqlite3.OperationalError: no such table: django_session

The above exception was the direct cause of the following exception:

Traceback (most recent call last):
  File "/usr/local/lib/python3.6/site-packages/django/core/handlers/exception.py", line 34, in inner
    response = get_response(request)
  File "/usr/local/lib/python3.6/site-packages/django/core/handlers/base.py", line 115, in _get_response
    response = self.process_exception_by_middleware(e, request)
  File "/usr/local/lib/python3.6/site-packages/django/core/handlers/base.py", line 113, in _get_response
    response = wrapped_callback(request, *callback_args, **callback_kwargs)
  File "./jariyo/views/base_views.py", line 11, in index
    if cur_user.is_authenticated:
  File "/usr/local/lib/python3.6/site-packages/django/utils/functional.py", line 224, in inner
    self._setup()
  File "/usr/local/lib/python3.6/site-packages/django/utils/functional.py", line 360, in _setup
    self._wrapped = self._setupfunc()
  File "/usr/local/lib/python3.6/site-packages/django/contrib/auth/middleware.py", line 24, in <lambda>
    request.user = SimpleLazyObject(lambda: get_user(request))
  File "/usr/local/lib/python3.6/site-packages/django/contrib/auth/middleware.py", line 12, in get_user
    request._cached_user = auth.get_user(request)
  File "/usr/local/lib/python3.6/site-packages/django/contrib/auth/__init__.py", line 173, in get_user
    user_id = _get_user_session_key(request)
  File "/usr/local/lib/python3.6/site-packages/django/contrib/auth/__init__.py", line 58, in _get_user_session_key
    return get_user_model()._meta.pk.to_python(request.session[SESSION_KEY])
  File "/usr/local/lib/python3.6/site-packages/django/contrib/sessions/backends/base.py", line 64, in __getitem__
    return self._session[key]
  File "/usr/local/lib/python3.6/site-packages/django/contrib/sessions/backends/base.py", line 204, in _get_session
    self._session_cache = self.load()
  File "/usr/local/lib/python3.6/site-packages/django/contrib/sessions/backends/db.py", line 43, in load
    s = self._get_session_from_db()
  File "/usr/local/lib/python3.6/site-packages/django/contrib/sessions/backends/db.py", line 34, in _get_session_from_db
    expire_date__gt=timezone.now()
  File "/usr/local/lib/python3.6/site-packages/django/db/models/manager.py", line 82, in manager_method
    return getattr(self.get_queryset(), name)(*args, **kwargs)
  File "/usr/local/lib/python3.6/site-packages/django/db/models/query.py", line 411, in get
    num = len(clone)
  File "/usr/local/lib/python3.6/site-packages/django/db/models/query.py", line 258, in __len__
    self._fetch_all()
  File "/usr/local/lib/python3.6/site-packages/django/db/models/query.py", line 1261, in _fetch_all
    self._result_cache = list(self._iterable_class(self))
  File "/usr/local/lib/python3.6/site-packages/django/db/models/query.py", line 57, in __iter__
    results = compiler.execute_sql(chunked_fetch=self.chunked_fetch, chunk_size=self.chunk_size)
  File "/usr/local/lib/python3.6/site-packages/django/db/models/sql/compiler.py", line 1151, in execute_sql
    cursor.execute(sql, params)
  File "/usr/local/lib/python3.6/site-packages/django/db/backends/utils.py", line 100, in execute
    return super().execute(sql, params)
  File "/usr/local/lib/python3.6/site-packages/django/db/backends/utils.py", line 68, in execute
    return self._execute_with_wrappers(sql, params, many=False, executor=self._execute)
  File "/usr/local/lib/python3.6/site-packages/django/db/backends/utils.py", line 77, in _execute_with_wrappers
    return executor(sql, params, many, context)
  File "/usr/local/lib/python3.6/site-packages/django/db/backends/utils.py", line 86, in _execute
    return self.cursor.execute(sql, params)
  File "/usr/local/lib/python3.6/site-packages/django/db/utils.py", line 90, in __exit__
    raise dj_exc_value.with_traceback(traceback) from exc_value
  File "/usr/local/lib/python3.6/site-packages/django/db/backends/utils.py", line 86, in _execute
    return self.cursor.execute(sql, params)
  File "/usr/local/lib/python3.6/site-packages/django/db/backends/sqlite3/base.py", line 396, in execute
    return Database.Cursor.execute(self, query, params)
django.db.utils.OperationalError: no such table: django_session
[pid: 8|app: 0|req: 19/19] 203.255.57.152 () {46 vars in 944 bytes} [Tue Nov  2 22:36:38 2021] GET / => generated 173629 bytes in 79 msecs (HTTP/1.1 500) 5 headers in 157 bytes (1 switches on core 0)
[pid: 8|app: 0|req: 20/20] 203.255.57.152 () {46 vars in 882 bytes} [Tue Nov  2 22:36:39 2021] GET / => generated 1911 bytes in 4 msecs (HTTP/1.1 200) 6 headers in 319 bytes (1 switches on core 1)
[pid: 8|app: 0|req: 21/21] 203.255.57.152 () {46 vars in 882 bytes} [Tue Nov  2 22:36:40 2021] GET / => generated 1911 bytes in 4 msecs (HTTP/1.1 200) 6 headers in 319 bytes (1 switches on core 0)
[pid: 8|app: 0|req: 22/22] 203.255.57.152 () {46 vars in 882 bytes} [Tue Nov  2 22:36:41 2021] GET / => generated 1911 bytes in 4 msecs (HTTP/1.1 200) 6 headers in 319 bytes (1 switches on core 1)
[pid: 8|app: 0|req: 23/23] 203.255.57.152 () {46 vars in 882 bytes} [Tue Nov  2 22:36:42 2021] GET / => generated 1911 bytes in 4 msecs (HTTP/1.1 200) 6 headers in 319 bytes (1 switches on core 0)
[pid: 8|app: 0|req: 24/24] 203.255.57.152 () {46 vars in 882 bytes} [Tue Nov  2 22:36:42 2021] GET / => generated 1911 bytes in 5 msecs (HTTP/1.1 200) 6 headers in 319 bytes (1 switches on core 1)
[pid: 8|app: 0|req: 25/25] 203.255.57.152 () {44 vars in 775 bytes} [Tue Nov  2 22:36:50 2021] GET / => generated 1911 bytes in 5 msecs (HTTP/1.1 200) 6 headers in 319 bytes (1 switches on core 0)
Not Found: /favicon.ico
[pid: 8|app: 0|req: 26/26] 203.255.57.152 () {46 vars in 817 bytes} [Tue Nov  2 22:36:51 2021] GET /favicon.ico => generated 2411 bytes in 5 msecs (HTTP/1.1 404) 4 headers in 129 bytes (1 switches on core 1)
Internal Server Error: /
Traceback (most recent call last):
  File "/usr/local/lib/python3.6/site-packages/django/contrib/sessions/backends/base.py", line 199, in _get_session
    return self._session_cache
AttributeError: 'SessionStore' object has no attribute '_session_cache'

During handling of the above exception, another exception occurred:

Traceback (most recent call last):
  File "/usr/local/lib/python3.6/site-packages/django/db/backends/utils.py", line 86, in _execute
    return self.cursor.execute(sql, params)
  File "/usr/local/lib/python3.6/site-packages/django/db/backends/sqlite3/base.py", line 396, in execute
    return Database.Cursor.execute(self, query, params)
sqlite3.OperationalError: no such table: django_session

The above exception was the direct cause of the following exception:

Traceback (most recent call last):
  File "/usr/local/lib/python3.6/site-packages/django/core/handlers/exception.py", line 34, in inner
    response = get_response(request)
  File "/usr/local/lib/python3.6/site-packages/django/core/handlers/base.py", line 115, in _get_response
    response = self.process_exception_by_middleware(e, request)
  File "/usr/local/lib/python3.6/site-packages/django/core/handlers/base.py", line 113, in _get_response
    response = wrapped_callback(request, *callback_args, **callback_kwargs)
  File "./jariyo/views/base_views.py", line 11, in index
    if cur_user.is_authenticated:
  File "/usr/local/lib/python3.6/site-packages/django/utils/functional.py", line 224, in inner
    self._setup()
  File "/usr/local/lib/python3.6/site-packages/django/utils/functional.py", line 360, in _setup
    self._wrapped = self._setupfunc()
  File "/usr/local/lib/python3.6/site-packages/django/contrib/auth/middleware.py", line 24, in <lambda>
    request.user = SimpleLazyObject(lambda: get_user(request))
  File "/usr/local/lib/python3.6/site-packages/django/contrib/auth/middleware.py", line 12, in get_user
    request._cached_user = auth.get_user(request)
  File "/usr/local/lib/python3.6/site-packages/django/contrib/auth/__init__.py", line 173, in get_user
    user_id = _get_user_session_key(request)
  File "/usr/local/lib/python3.6/site-packages/django/contrib/auth/__init__.py", line 58, in _get_user_session_key
    return get_user_model()._meta.pk.to_python(request.session[SESSION_KEY])
  File "/usr/local/lib/python3.6/site-packages/django/contrib/sessions/backends/base.py", line 64, in __getitem__
    return self._session[key]
  File "/usr/local/lib/python3.6/site-packages/django/contrib/sessions/backends/base.py", line 204, in _get_session
    self._session_cache = self.load()
  File "/usr/local/lib/python3.6/site-packages/django/contrib/sessions/backends/db.py", line 43, in load
    s = self._get_session_from_db()
  File "/usr/local/lib/python3.6/site-packages/django/contrib/sessions/backends/db.py", line 34, in _get_session_from_db
    expire_date__gt=timezone.now()
  File "/usr/local/lib/python3.6/site-packages/django/db/models/manager.py", line 82, in manager_method
    return getattr(self.get_queryset(), name)(*args, **kwargs)
  File "/usr/local/lib/python3.6/site-packages/django/db/models/query.py", line 411, in get
    num = len(clone)
  File "/usr/local/lib/python3.6/site-packages/django/db/models/query.py", line 258, in __len__
    self._fetch_all()
  File "/usr/local/lib/python3.6/site-packages/django/db/models/query.py", line 1261, in _fetch_all
    self._result_cache = list(self._iterable_class(self))
  File "/usr/local/lib/python3.6/site-packages/django/db/models/query.py", line 57, in __iter__
    results = compiler.execute_sql(chunked_fetch=self.chunked_fetch, chunk_size=self.chunk_size)
  File "/usr/local/lib/python3.6/site-packages/django/db/models/sql/compiler.py", line 1151, in execute_sql
    cursor.execute(sql, params)
  File "/usr/local/lib/python3.6/site-packages/django/db/backends/utils.py", line 100, in execute
    return super().execute(sql, params)
  File "/usr/local/lib/python3.6/site-packages/django/db/backends/utils.py", line 68, in execute
    return self._execute_with_wrappers(sql, params, many=False, executor=self._execute)
  File "/usr/local/lib/python3.6/site-packages/django/db/backends/utils.py", line 77, in _execute_with_wrappers
    return executor(sql, params, many, context)
  File "/usr/local/lib/python3.6/site-packages/django/db/backends/utils.py", line 86, in _execute
    return self.cursor.execute(sql, params)
  File "/usr/local/lib/python3.6/site-packages/django/db/utils.py", line 90, in __exit__
    raise dj_exc_value.with_traceback(traceback) from exc_value
  File "/usr/local/lib/python3.6/site-packages/django/db/backends/utils.py", line 86, in _execute
    return self.cursor.execute(sql, params)
  File "/usr/local/lib/python3.6/site-packages/django/db/backends/sqlite3/base.py", line 396, in execute
    return Database.Cursor.execute(self, query, params)
django.db.utils.OperationalError: no such table: django_session
[pid: 8|app: 0|req: 27/27] 203.255.57.152 () {44 vars in 913 bytes} [Tue Nov  2 22:37:03 2021] GET / => generated 173490 bytes in 76 msecs (HTTP/1.1 500) 5 headers in 157 bytes (1 switches on core 0)
[pid: 8|app: 0|req: 28/28] 203.255.57.152 () {42 vars in 759 bytes} [Tue Nov  2 22:37:29 2021] GET / => generated 1911 bytes in 4 msecs (HTTP/1.1 200) 6 headers in 319 bytes (1 switches on core 1)
[pid: 8|app: 0|req: 29/29] 203.255.57.152 () {52 vars in 1074 bytes} [Tue Nov  2 22:37:35 2021] POST /account/login/ => generated 2012 bytes in 9 msecs (HTTP/1.1 200) 8 headers in 431 bytes (1 switches on core 0)
[pid: 8|app: 0|req: 30/30] 203.255.57.152 () {54 vars in 1091 bytes} [Tue Nov  2 22:37:37 2021] POST /account/login/ => generated 2012 bytes in 5 msecs (HTTP/1.1 200) 8 headers in 431 bytes (1 switches on core 1)
Internal Server Error: /account/login/
Traceback (most recent call last):
  File "/usr/local/lib/python3.6/site-packages/django/db/backends/utils.py", line 86, in _execute
    return self.cursor.execute(sql, params)
  File "/usr/local/lib/python3.6/site-packages/django/db/backends/sqlite3/base.py", line 396, in execute
    return Database.Cursor.execute(self, query, params)
sqlite3.OperationalError: no such table: auth_user

The above exception was the direct cause of the following exception:

Traceback (most recent call last):
  File "/usr/local/lib/python3.6/site-packages/django/core/handlers/exception.py", line 34, in inner
    response = get_response(request)
  File "/usr/local/lib/python3.6/site-packages/django/core/handlers/base.py", line 115, in _get_response
    response = self.process_exception_by_middleware(e, request)
  File "/usr/local/lib/python3.6/site-packages/django/core/handlers/base.py", line 113, in _get_response
    response = wrapped_callback(request, *callback_args, **callback_kwargs)
  File "/usr/local/lib/python3.6/site-packages/django/views/generic/base.py", line 71, in view
    return self.dispatch(request, *args, **kwargs)
  File "/usr/local/lib/python3.6/site-packages/django/utils/decorators.py", line 43, in _wrapper
    return bound_method(*args, **kwargs)
  File "/usr/local/lib/python3.6/site-packages/django/views/decorators/debug.py", line 76, in sensitive_post_parameters_wrapper
    return view(request, *args, **kwargs)
  File "/usr/local/lib/python3.6/site-packages/django/utils/decorators.py", line 43, in _wrapper
    return bound_method(*args, **kwargs)
  File "/usr/local/lib/python3.6/site-packages/django/utils/decorators.py", line 130, in _wrapped_view
    response = view_func(request, *args, **kwargs)
  File "/usr/local/lib/python3.6/site-packages/django/utils/decorators.py", line 43, in _wrapper
    return bound_method(*args, **kwargs)
  File "/usr/local/lib/python3.6/site-packages/django/views/decorators/cache.py", line 44, in _wrapped_view_func
    response = view_func(request, *args, **kwargs)
  File "/usr/local/lib/python3.6/site-packages/django/contrib/auth/views.py", line 63, in dispatch
    return super().dispatch(request, *args, **kwargs)
  File "/usr/local/lib/python3.6/site-packages/django/views/generic/base.py", line 97, in dispatch
    return handler(request, *args, **kwargs)
  File "/usr/local/lib/python3.6/site-packages/django/views/generic/edit.py", line 141, in post
    if form.is_valid():
  File "/usr/local/lib/python3.6/site-packages/django/forms/forms.py", line 180, in is_valid
    return self.is_bound and not self.errors
  File "/usr/local/lib/python3.6/site-packages/django/forms/forms.py", line 175, in errors
    self.full_clean()
  File "/usr/local/lib/python3.6/site-packages/django/forms/forms.py", line 377, in full_clean
    self._clean_form()
  File "/usr/local/lib/python3.6/site-packages/django/forms/forms.py", line 404, in _clean_form
    cleaned_data = self.clean()
  File "/usr/local/lib/python3.6/site-packages/django/contrib/auth/forms.py", line 214, in clean
    self.user_cache = authenticate(self.request, username=username, password=password)
  File "/usr/local/lib/python3.6/site-packages/django/contrib/auth/__init__.py", line 72, in authenticate
    user = backend.authenticate(request, **credentials)
  File "/usr/local/lib/python3.6/site-packages/django/contrib/auth/backends.py", line 46, in authenticate
    user = UserModel._default_manager.get_by_natural_key(username)
  File "/usr/local/lib/python3.6/site-packages/django/contrib/auth/base_user.py", line 44, in get_by_natural_key
    return self.get(**{self.model.USERNAME_FIELD: username})
  File "/usr/local/lib/python3.6/site-packages/django/db/models/manager.py", line 82, in manager_method
    return getattr(self.get_queryset(), name)(*args, **kwargs)
  File "/usr/local/lib/python3.6/site-packages/django/db/models/query.py", line 411, in get
    num = len(clone)
  File "/usr/local/lib/python3.6/site-packages/django/db/models/query.py", line 258, in __len__
    self._fetch_all()
  File "/usr/local/lib/python3.6/site-packages/django/db/models/query.py", line 1261, in _fetch_all
    self._result_cache = list(self._iterable_class(self))
  File "/usr/local/lib/python3.6/site-packages/django/db/models/query.py", line 57, in __iter__
    results = compiler.execute_sql(chunked_fetch=self.chunked_fetch, chunk_size=self.chunk_size)
  File "/usr/local/lib/python3.6/site-packages/django/db/models/sql/compiler.py", line 1151, in execute_sql
    cursor.execute(sql, params)
  File "/usr/local/lib/python3.6/site-packages/django/db/backends/utils.py", line 100, in execute
    return super().execute(sql, params)
  File "/usr/local/lib/python3.6/site-packages/django/db/backends/utils.py", line 68, in execute
    return self._execute_with_wrappers(sql, params, many=False, executor=self._execute)
  File "/usr/local/lib/python3.6/site-packages/django/db/backends/utils.py", line 77, in _execute_with_wrappers
    return executor(sql, params, many, context)
  File "/usr/local/lib/python3.6/site-packages/django/db/backends/utils.py", line 86, in _execute
    return self.cursor.execute(sql, params)
  File "/usr/local/lib/python3.6/site-packages/django/db/utils.py", line 90, in __exit__
    raise dj_exc_value.with_traceback(traceback) from exc_value
  File "/usr/local/lib/python3.6/site-packages/django/db/backends/utils.py", line 86, in _execute
    return self.cursor.execute(sql, params)
  File "/usr/local/lib/python3.6/site-packages/django/db/backends/sqlite3/base.py", line 396, in execute
    return Database.Cursor.execute(self, query, params)
django.db.utils.OperationalError: no such table: auth_user
[pid: 8|app: 0|req: 31/31] 203.255.57.152 () {52 vars in 1088 bytes} [Tue Nov  2 22:37:41 2021] POST /account/login/ => generated 208962 bytes in 85 msecs (HTTP/1.1 500) 5 headers in 157 bytes (1 switches on core 0)
Internal Server Error: /account/login/
Traceback (most recent call last):
  File "/usr/local/lib/python3.6/site-packages/django/db/backends/utils.py", line 86, in _execute
    return self.cursor.execute(sql, params)
  File "/usr/local/lib/python3.6/site-packages/django/db/backends/sqlite3/base.py", line 396, in execute
    return Database.Cursor.execute(self, query, params)
sqlite3.OperationalError: no such table: auth_user

The above exception was the direct cause of the following exception:

Traceback (most recent call last):
  File "/usr/local/lib/python3.6/site-packages/django/core/handlers/exception.py", line 34, in inner
    response = get_response(request)
  File "/usr/local/lib/python3.6/site-packages/django/core/handlers/base.py", line 115, in _get_response
    response = self.process_exception_by_middleware(e, request)
  File "/usr/local/lib/python3.6/site-packages/django/core/handlers/base.py", line 113, in _get_response
    response = wrapped_callback(request, *callback_args, **callback_kwargs)
  File "/usr/local/lib/python3.6/site-packages/django/views/generic/base.py", line 71, in view
    return self.dispatch(request, *args, **kwargs)
  File "/usr/local/lib/python3.6/site-packages/django/utils/decorators.py", line 43, in _wrapper
    return bound_method(*args, **kwargs)
  File "/usr/local/lib/python3.6/site-packages/django/views/decorators/debug.py", line 76, in sensitive_post_parameters_wrapper
    return view(request, *args, **kwargs)
  File "/usr/local/lib/python3.6/site-packages/django/utils/decorators.py", line 43, in _wrapper
    return bound_method(*args, **kwargs)
  File "/usr/local/lib/python3.6/site-packages/django/utils/decorators.py", line 130, in _wrapped_view
    response = view_func(request, *args, **kwargs)
  File "/usr/local/lib/python3.6/site-packages/django/utils/decorators.py", line 43, in _wrapper
    return bound_method(*args, **kwargs)
  File "/usr/local/lib/python3.6/site-packages/django/views/decorators/cache.py", line 44, in _wrapped_view_func
    response = view_func(request, *args, **kwargs)
  File "/usr/local/lib/python3.6/site-packages/django/contrib/auth/views.py", line 63, in dispatch
    return super().dispatch(request, *args, **kwargs)
  File "/usr/local/lib/python3.6/site-packages/django/views/generic/base.py", line 97, in dispatch
    return handler(request, *args, **kwargs)
  File "/usr/local/lib/python3.6/site-packages/django/views/generic/edit.py", line 141, in post
    if form.is_valid():
  File "/usr/local/lib/python3.6/site-packages/django/forms/forms.py", line 180, in is_valid
    return self.is_bound and not self.errors
  File "/usr/local/lib/python3.6/site-packages/django/forms/forms.py", line 175, in errors
    self.full_clean()
  File "/usr/local/lib/python3.6/site-packages/django/forms/forms.py", line 377, in full_clean
    self._clean_form()
  File "/usr/local/lib/python3.6/site-packages/django/forms/forms.py", line 404, in _clean_form
    cleaned_data = self.clean()
  File "/usr/local/lib/python3.6/site-packages/django/contrib/auth/forms.py", line 214, in clean
    self.user_cache = authenticate(self.request, username=username, password=password)
  File "/usr/local/lib/python3.6/site-packages/django/contrib/auth/__init__.py", line 72, in authenticate
    user = backend.authenticate(request, **credentials)
  File "/usr/local/lib/python3.6/site-packages/django/contrib/auth/backends.py", line 46, in authenticate
    user = UserModel._default_manager.get_by_natural_key(username)
  File "/usr/local/lib/python3.6/site-packages/django/contrib/auth/base_user.py", line 44, in get_by_natural_key
    return self.get(**{self.model.USERNAME_FIELD: username})
  File "/usr/local/lib/python3.6/site-packages/django/db/models/manager.py", line 82, in manager_method
    return getattr(self.get_queryset(), name)(*args, **kwargs)
  File "/usr/local/lib/python3.6/site-packages/django/db/models/query.py", line 411, in get
    num = len(clone)
  File "/usr/local/lib/python3.6/site-packages/django/db/models/query.py", line 258, in __len__
    self._fetch_all()
  File "/usr/local/lib/python3.6/site-packages/django/db/models/query.py", line 1261, in _fetch_all
    self._result_cache = list(self._iterable_class(self))
  File "/usr/local/lib/python3.6/site-packages/django/db/models/query.py", line 57, in __iter__
    results = compiler.execute_sql(chunked_fetch=self.chunked_fetch, chunk_size=self.chunk_size)
  File "/usr/local/lib/python3.6/site-packages/django/db/models/sql/compiler.py", line 1151, in execute_sql
    cursor.execute(sql, params)
  File "/usr/local/lib/python3.6/site-packages/django/db/backends/utils.py", line 100, in execute
    return super().execute(sql, params)
  File "/usr/local/lib/python3.6/site-packages/django/db/backends/utils.py", line 68, in execute
    return self._execute_with_wrappers(sql, params, many=False, executor=self._execute)
  File "/usr/local/lib/python3.6/site-packages/django/db/backends/utils.py", line 77, in _execute_with_wrappers
    return executor(sql, params, many, context)
  File "/usr/local/lib/python3.6/site-packages/django/db/backends/utils.py", line 86, in _execute
    return self.cursor.execute(sql, params)
  File "/usr/local/lib/python3.6/site-packages/django/db/utils.py", line 90, in __exit__
    raise dj_exc_value.with_traceback(traceback) from exc_value
  File "/usr/local/lib/python3.6/site-packages/django/db/backends/utils.py", line 86, in _execute
    return self.cursor.execute(sql, params)
  File "/usr/local/lib/python3.6/site-packages/django/db/backends/sqlite3/base.py", line 396, in execute
    return Database.Cursor.execute(self, query, params)
django.db.utils.OperationalError: no such table: auth_user
[pid: 8|app: 0|req: 32/32] 203.255.57.152 () {52 vars in 1078 bytes} [Tue Nov  2 22:37:42 2021] POST /account/login/ => generated 208912 bytes in 87 msecs (HTTP/1.1 500) 5 headers in 157 bytes (1 switches on core 1)
[pid: 8|app: 0|req: 33/33] 203.255.57.152 () {44 vars in 847 bytes} [Tue Nov  2 22:37:46 2021] GET / => generated 1911 bytes in 5 msecs (HTTP/1.1 200) 6 headers in 319 bytes (1 switches on core 0)
[pid: 8|app: 0|req: 34/34] 182.172.56.228 () {42 vars in 764 bytes} [Tue Nov  2 22:37:48 2021] GET / => generated 1911 bytes in 5 msecs (HTTP/1.1 200) 6 headers in 319 bytes (1 switches on core 1)
[pid: 8|app: 0|req: 35/35] 203.255.57.152 () {46 vars in 914 bytes} [Tue Nov  2 22:37:48 2021] GET /account/signup/ => generated 2858 bytes in 20 msecs (HTTP/1.1 200) 6 headers in 319 bytes (1 switches on core 0)
[pid: 8|app: 0|req: 36/36] 203.255.57.152 () {44 vars in 844 bytes} [Tue Nov  2 22:39:05 2021] GET / => generated 1911 bytes in 4 msecs (HTTP/1.1 200) 6 headers in 319 bytes (1 switches on core 1)
[pid: 8|app: 0|req: 37/37] 203.255.57.152 () {44 vars in 850 bytes} [Tue Nov  2 22:44:07 2021] GET / => generated 1911 bytes in 3 msecs (HTTP/1.1 200) 6 headers in 319 bytes (1 switches on core 0)
Not Found: /favicon.ico
[pid: 8|app: 0|req: 38/38] 203.255.57.152 () {44 vars in 803 bytes} [Tue Nov  2 22:44:08 2021] GET /favicon.ico => generated 2411 bytes in 5 msecs (HTTP/1.1 404) 4 headers in 129 bytes (1 switches on core 1)
[pid: 8|app: 0|req: 39/39] 203.255.57.152 () {44 vars in 860 bytes} [Tue Nov  2 22:44:14 2021] GET /admin => generated 0 bytes in 2 msecs (HTTP/1.1 301) 4 headers in 145 bytes (1 switches on core 0)
[pid: 8|app: 0|req: 40/40] 203.255.57.152 () {44 vars in 862 bytes} [Tue Nov  2 22:44:14 2021] GET /admin/ => generated 0 bytes in 11 msecs (HTTP/1.1 302) 8 headers in 301 bytes (1 switches on core 0)
[pid: 8|app: 0|req: 41/41] 203.255.57.152 () {44 vars in 899 bytes} [Tue Nov  2 22:44:14 2021] GET /admin/login/?next=/admin/ => generated 1933 bytes in 31 msecs (HTTP/1.1 200) 8 headers in 431 bytes (1 switches on core 1)
[pid: 8|app: 0|req: 42/42] 203.255.57.152 () {52 vars in 1123 bytes} [Tue Nov  2 22:44:19 2021] POST /admin/login/?next=/admin/ => generated 0 bytes in 201 msecs (HTTP/1.1 302) 10 headers in 595 bytes (1 switches on core 0)
[pid: 8|app: 0|req: 43/43] 203.255.57.152 () {48 vars in 999 bytes} [Tue Nov  2 22:44:20 2021] GET /admin/ => generated 4421 bytes in 29 msecs (HTTP/1.1 200) 7 headers in 263 bytes (1 switches on core 1)
[pid: 8|app: 0|req: 44/44] 184.105.139.67 () {28 vars in 297 bytes} [Tue Nov  2 22:56:43 2021] GET / => generated 1911 bytes in 6 msecs (HTTP/1.1 200) 6 headers in 319 bytes (1 switches on core 0)
[pid: 8|app: 0|req: 45/45] 176.53.221.213 () {36 vars in 516 bytes} [Tue Nov  2 22:57:28 2021] GET / => generated 1911 bytes in 6 msecs (HTTP/1.1 200) 6 headers in 319 bytes (1 switches on core 1)
Not Found: /favicon.ico
[pid: 8|app: 0|req: 46/46] 176.53.219.99 () {36 vars in 537 bytes} [Tue Nov  2 22:57:28 2021] GET /favicon.ico => generated 2412 bytes in 7 msecs (HTTP/1.1 404) 4 headers in 129 bytes (1 switches on core 0)
